Workbook

Sheet README
A1: Panel mensual para evaluar oferta de 1% en minera de cobre
A3: Qué trae este archivo | B3: Un panel mensual desde 2021-02 hasta 2026-02. Las columnas azules son para pegar tus series. Las verdes ya vienen cargadas con datos públicos mensuales de Chile. Las amarillas calculan variables útiles para la regresión.
A4: Columnas que debes pegar | B4: dividendo_total_nominal, ipc, cobre_usd_metric_ton, fx_clp_usd. Si más adelante consigues datos de la faena específica, pega produccion_mina_tmf y ley_mina_pct.
A5: Variables públicas ya cargadas | B5: ipmin_index, grupo_040_cobre_index, ipmin_excl_cobre_index, iimcu_index, iimcu_productos_index, iimcu_insumos_index, cobre_tmf_chile, molibdeno_tmf_chile, oro_kg_fino_chile y plata_kg_fino_chile.
A6: Qué no pude completar | B6: No pude completar produccion_mina_tmf ni ley_mina_pct de la mina específica sin el nombre de la faena o la empresa y sin una fuente mensual pública equivalente. Lo que sí cargué son proxies públicos de actividad y producción de la minería del cobre en Chile.
A7: Cobertura | B7: Las series públicas verificadas y descargadas en esta corrida llegan hasta enero 2026. Dejé febrero 2026 con espacio reservado para que pegues tus propios datos y para completar luego el dato público cuando esté confirmado.
A8: Sugerencia de primer modelo | B8: Empieza con ln1p_dividendo_real como dependiente, y como explicativas usa ln_cobre_real, grupo_040_cobre_index, iimcu_insumos_index, dummies mensuales y un rezago del dividendo. Al principio usa la serie sin desestacionalizar y controla con dummies mensuales.
A9: Lectura rápida de proxies | B9: grupo_040_cobre_index funciona como proxy de actividad del cobre. iimcu_productos_index puede captar acumulación de inventarios de productos. iimcu_insumos_index puede captar tensión de insumos o compras para producción futura. cobre_tmf_chile y molibdeno_tmf_chile ayudan a capturar ciclo productivo y créditos por subproductos.
A12: Clave de colores
A13: Azul | B13: Pega aquí tus datos
A14: Verde | B14: Datos públicos ya cargados
A15: Amarillo | B15: Fórmulas y variables derivadas

Sheet diccionario
A1: variable | B1: tipo | C1: unidad | D1: llenado | E1: descripcion | F1: fuente / nota
A2: fecha | B2: fecha | C2: mes | D2: archivo | E2: Primer día de cada mes | F2: Rango 2021-02 a 2026-02
A3: dividendo_total_nominal | B3: nivel | C3: CLP nominal | D3: usuario | E3: Dividendo total repartido por la minera en el mes | F3: Tu serie
A4: ipc | B4: índice | C4: base de tu fuente | D4: usuario | E4: IPC mensual para deflactar | F4: Tu serie
A5: cobre_usd_metric_ton | B5: precio | C5: USD por tonelada métrica | D5: usuario | E5: Precio del cobre mensual | F5: Tu serie
A6: fx_clp_usd | B6: tipo de cambio | C6: CLP por USD | D6: usuario | E6: Tipo de cambio promedio mensual | F6: Tu serie
A7: anio | B7: derivada | C7: año | D7: fórmula | E7: Año de la fecha | F7: YEAR(fecha)
A8: mes | B8: derivada | C8: 1-12 | D8: fórmula | E8: Mes numérico | F8: MONTH(fecha)
A9: cobre_clp_metric_ton | B9: derivada | C9: CLP por tonelada métrica | D9: fórmula | E9: Precio del cobre en pesos | F9: cobre_usd_metric_ton * fx_clp_usd
A10: dividendo_real_base_ultimo_ipc | B10: derivada | C10: CLP reales | D10: fórmula | E10: Dividendo deflactado usando el último IPC no vacío como base | F10: Útil para regresión en términos reales
A11: cobre_real_clp_metric_ton_base_ultimo_ipc | B11: derivada | C11: CLP reales por tonelada | D11: fórmula | E11: Cobre en CLP reales usando el último IPC no vacío como base | F11: Útil para elasticidades
A12: cobre_bajo_q25 | B12: derivada | C12: dummy 0/1 | D12: fórmula | E12: Vale 1 si el cobre en USD está en el cuartil inferior de la muestra disponible | F12: Útil para estudiar meses malos
... A26: ley_mina_pct | B26: ley | C26: % | D26: usuario | E26: Ley de la faena específica | F26: Reservado para completar si consigues el dato
A27: comentario | B27: texto | D27: archivo | E27: Notas de disponibilidad o calidad del dato | F27: Feb-2026 quedó reservado

Sheet fuentes
A1: tipo | B1: fuente | C1: url | D1: cobertura / nota
A2: usada | B2: INE - series empalmadas y mensuales de minería (IPMin) a enero 2026 | C2: https://www.ine.gob.cl/docs/default-source/mineria/cuadros-estadisticos/base-promedio-2018-100/series-empalmadas-y-mensuales-a-enero-2026.xls | D2: De aquí salen ipmin_index, grupo_040_cobre_index, ipmin_excl_cobre_index y las producciones mensuales de cobre, molibdeno, oro y plata.
A3: usada | B3: INE - series empalmadas y mensuales del inventario de la minería del cobre a enero 2026 | C3: https://www.ine.gob.cl/docs/default-source/inventarios-de-la-miner%C3%ADa-del-cobre/cuadros-estadisticos/base-diciembre-2018-100/series-empalmadas-y-mensuales-a-enero-2026.xls | D3: De aquí salen iimcu_index, iimcu_productos_index e iimcu_insumos_index.
A4: referencia | B4: INE - estadísticas de minería | C4: https://www.ine.gob.cl/estadisticas/economia/mineria | D4: Página pública general de minería del INE.
A5: complementaria | B5: Cochilco - histórico de producción de cobre y molibdeno | C5: https://www.cochilco.cl/web/historico-produccion-de-cobre-y-molibdeno/ | D5: Fuente complementaria útil para ampliar o contrastar series.
A6: complementaria | B6: Cochilco - histórico precio de los metales | C6: https://www.cochilco.cl/web/historico-precio-de-los-metales/ | D6: Fuente complementaria útil para contrastar cobre y molibdeno.
A7: complementaria | B7: Cochilco - histórico inventarios mundiales de cobre | C7: https://www.cochilco.cl/web/historico-inventarios-mundiales-de-cobre/ | D7: Fuente complementaria útil para agregar un control de mercado global.

Sheet config
A1: ultimo_ipc_no_vacio | B1: =LOOKUP(2,1/(panel_regresion!$C$2:$C$77<>""),panel_regresion!$C$2:$C$77) -> 109.7
A2: q25_cobre_usd_metric_ton | B2: =_xludf.PERCENTILE.INC(panel_regresion!$D$2:$D$77,0.25) -> #NAME?
A3: nota | B3: Esta hoja queda oculta. Solo contiene referencias para fórmulas.

Sheet panel_regresion
A1: fecha | B1: dividendo_total_nominal | C1: ipc | D1: cobre_usd_metric_ton | E1: fx_clp_usd | F1: anio | G1: mes | H1: cobre_clp_metric_ton | I1: dividendo_real_base_ultimo_ipc | J1: cobre_real_clp_metric_ton_base_ultimo_ipc | K1: cobre_bajo_q25 | L1: ln1p_dividendo_real | M1: ln_cobre_real | N1: ipmin_index | O1: grupo_040_cobre_index | P1: ipmin_excl_cobre_index | Q1: iimcu_index | R1: iimcu_productos_index | S1: iimcu_insumos_index | T1: cobre_tmf_chile | U1: molibdeno_tmf_chile | V1: oro_kg_fino_chile | W1: plata_kg_fino_chile | X1: dry_tons | Y1: grade | Z1: regalia
A2: 43790 | C2: 78.03 | D2: 5859.95 | E2: 776.53 | F2: =YEAR(A2) -> 2019 | G2: =MONTH(A2) -> 11 | H2: =IF(OR(D2="",E2=""),"",D2*E2) -> 4550427 | I2: =IF(OR(B2="",C2="",config!$B$1=""),"",B2/(C2/config!$B$1)) | J2: =IF(OR(H2="",C2="",config!$B$1=""),"",H2/(C2/config!$B$1)) -> 6397306.7 | L2: =IF(I2="","",LN(1+MAX(0,I2))) | M2: =IF(J2="","",LN(J2)) -> 15.671388 | N2: 86.62828 | O2: 85.713078 | P2: 94.031056 | Q2: 108.46186 | R2: 102.6852 | S2: 134.15573 | T2: 427846 | U2: 3709 | V2: 2161 | W2: 92996 | X2: 2106.7 | Y2: 2.21 | Z2: =IF(Y2<=2.41,10%,15%) -> 0.1
A3: 43821 | C3: 78.1 | D3: 6077.06 | E3: 770.39 | F3: =YEAR(A3) -> 2019 | G3: =MONTH(A3) -> 12 | H3: =IF(OR(D3="",E3=""),"",D3*E3) -> 4681706.3 | I3: =IF(OR(B3="",C3="",config!$B$1=""),"",B3/(C3/config!$B$1)) | J3: =IF(OR(H3="",C3="",config!$B$1=""),"",H3/(C3/config!$B$1)) -> 6575969 | L3: =IF(I3="","",LN(1+MAX(0,I3))) | M3: =IF(J3="","",LN(J3)) -> 15.698932 | N3: 86.62828 | O3: 85.713078 | P3: 94.031056 | Q3: 108.46186 | R3: 102.6852 | S3: 134.15573 | T3: 427846 | U3: 3709 | V3: 2161 | W3: 92996 | X3: 2616.8 | Y3: 2.47
A4: 43853 | C4: 78.55 | D4: 6031.21 | E4: 772.65 | F4: =YEAR(A4) -> 2020 | G4: =MONTH(A4) -> 1 | H4: =IF(OR(D4="",E4=""),"",D4*E4) -> 4660014.4 | I4: =IF(OR(B4="",C4="",config!$B$1=""),"",B4/(C4/config!$B$1)) | J4: =IF(OR(H4="",C4="",config!$B$1=""),"",H4/(C4/config!$B$1)) -> 6508002.3 | L4: =IF(I4="","",LN(1+MAX(0,I4))) | M4: =IF(J4="","",LN(J4)) -> 15.688543 | N4: 86.62828 | O4: 85.713078 | P4: 94.031056 | Q4: 108.46186 | R4: 102.6852 | S4: 134.15573 | T4: 427846 | U4: 3709 | V4: 2161 | W4: 92996 | X4: 2657.7 | Y4: 2.05 | Z4: =IF(Y4<=2.41,10%,15%) -> 0.1
A5: 43885 | C5: 78.9 | D5: 5687.75 | E5: 796.38 | F5: =YEAR(A5) -> 2020 | G5: =MONTH(A5) -> 2 | H5: =IF(OR(D5="",E5=""),"",D5*E5) -> 4529610.3 | I5: =IF(OR(B5="",C5="",config!$B$1=""),"",B5/(C5/config!$B$1)) | J5: =IF(OR(H5="",C5="",config!$B$1=""),"",H5/(C5/config!$B$1)) -> 6297823.3 | L5: =IF(I5="","",LN(1+MAX(0,I5))) | M5: =IF(J5="","",LN(J5)) -> 15.655715 | N5: 86.62828 | O5: 85.713078 | P5: 94.031056 | Q5: 108.46186 | R5: 102.6852 | S5: 134.15573 | T5: 427846 | U5: 3709 | V5: 2161 | W5: 92996 | X5: 876 | Y5: 1.7 | Z5: =IF(Y5<=2.41,10%,15%) -> 0.1
A6: 43916 | C6: 79.16 | D6: 5182.63 | E6: 839.38 | F6: =YEAR(A6) -> 2020 | G6: =MONTH(A6) -> 3 | H6: =IF(OR(D6="",E6=""),"",D6*E6) -> 4350196 | I6: =IF(OR(B6="",C6="",config!$B$1=""),"",B6/(C6/config!$B$1)) | J6: =IF(OR(H6="",C6="",config!$B$1=""),"",H6/(C6/config!$B$1)) -> 6028505.5 | L6: =IF(I6="","",LN(1+MAX(0,I6))) | M6: =IF(J6="","",LN(J6)) -> 15.61201 | N6: 86.62828 | O6: 85.713078 | P6: 94.031056 | Q6: 108.46186 | R6: 102.6852 | S6: 134.15573 | T6: 427846 | U6: 3709 | V6: 2161 | W6: 92996 | Z6: =IF(Y6<=2.41,10%,15%) -> 0.1
A7: 43947 | C7: 79.13 | D7: 5057.97 | E7: 853.38 | F7: =YEAR(A7) -> 2020 | G7: =MONTH(A7) -> 4 | H7: =IF(OR(D7="",E7=""),"",D7*E7) -> 4316370.4 | I7: =IF(OR(B7="",C7="",config!$B$1=""),"",B7/(C7/config!$B$1)) | J7: =IF(OR(H7="",C7="",config!$B$1=""),"",H7/(C7/config!$B$1)) -> 5983897.9 | L7: =IF(I7="","",LN(1+MAX(0,I7))) | M7: =IF(J7="","",LN(J7)) -> 15.604583 | N7: 86.62828 | O7: 85.713078 | P7: 94.031056 | Q7: 108.46186 | R7: 102.6852 | S7: 134.15573 | T7: 427846 | U7: 3709 | V7: 2161 | W7: 92996 | Z7: =IF(Y7<=2.41,10%,15%) -> 0.1
A8: 43978 | C8: 79.09 | D8: 5239.83 | E8: 821.81 | F8: =YEAR(A8) -> 2020 | G8: =MONTH(A8) -> 5 | H8: =IF(OR(D8="",E8=""),"",D8*E8) -> 4306144.7 | I8: =IF(OR(B8="",C8="",config!$B$1=""),"",B8/(C8/config!$B$1)) | J8: =IF(OR(H8="",C8="",config!$B$1=""),"",H8/(C8/config!$B$1)) -> 5972740.8 | L8: =IF(I8="","",LN(1+MAX(0,I8))) | M8: =IF(J8="","",LN(J8)) -> 15.602716 | N8: 86.62828 | O8: 85.713078 | P8: 94.031056 | Q8: 108.46186 | R8: 102.6852 | S8: 134.15573 | T8: 427846 | U8: 3709 | V8: 2161 | W8: 92996 | Z8: =IF(Y8<=2.41,10%,15%) -> 0.1
A9: 44009 | C9: 79.03 | D9: 5754.6 | E9: 793.72 | F9: =YEAR(A9) -> 2020 | G9: =MONTH(A9) -> 6 | H9: =IF(OR(D9="",E9=""),"",D9*E9) -> 4567541.1 | I9: =IF(OR(B9="",C9="",config!$B$1=""),"",B9/(C9/config!$B$1)) | J9: =IF(OR(H9="",C9="",config!$B$1=""),"",H9/(C9/config!$B$1)) -> 6340114.6 | L9: =IF(I9="","",LN(1+MAX(0,I9))) | M9: =IF(J9="","",LN(J9)) -> 15.662407 | N9: 86.62828 | O9: 85.713078 | P9: 94.031056 | Q9: 108.46186 | R9: 102.6852 | S9: 134.15573 | T9: 427846 | U9: 3709 | V9: 2161 | W9: 92996 | X9: 2315 | Y9: 3.6164 | Z9: =IF(Y9<=2.41,10%,15%) -> 0.15
A10: 44040 | B10: 12000000 | C10: 79.11 | D10: 6372.46 | E10: 784.73 | F10: =YEAR(A10) -> 2020 | G10: =MONTH(A10) -> 7 | H10: =IF(OR(D10="",E10=""),"",D10*E10) -> 5000660.5 | I10: =IF(OR(B10="",C10="",config!$B$1=""),"",B10/(C10/config!$B$1)) -> 16640121 | J10: =IF(OR(H10="",C10="",config!$B$1=""),"",H10/(C10/config!$B$1)) -> 6934299.8 | L10: =IF(I10="","",LN(1+MAX(0,I10))) -> 16.627327 | M10: =IF(J10="","",LN(J10)) -> 15.751991 | N10: 86.62828 | O10: 85.713078 | P10: 94.031056 | Q10: 108.46186 | R10: 102.6852 | S10: 134.15573 | T10: 427846 | U10: 3709 | V10: 2161 | W10: 92996 | X10: 1179.3 | Y10: 3.5254 | Z10: =IF(Y10<=2.41,10%,15%) -> 0.15
A11: 44071 | B11: 24000000 | C11: 79.22 | D11: 6508.39 | E11: 784.66 | F11: =YEAR(A11) -> 2020 | G11: =MONTH(A11) -> 8 | H11: =IF(OR(D11="",E11=""),"",D11*E11) -> 5106873.3 | I11: =IF(OR(B11="",C11="",config!$B$1=""),"",B11/(C11/config!$B$1)) -> 33234032 | J11: =IF(OR(H11="",C11="",config!$B$1=""),"",H11/(C11/config!$B$1)) -> 7071749.6 | L11: =IF(I11="","",LN(1+MAX(0,I11))) -> 17.319085 | M11: =IF(J11="","",LN(J11)) -> 15.771618 | N11: 86.62828 | O11: 85.713078 | P11: 94.031056 | Q11: 108.46186 | R11: 102.6852 | S11: 134.15573 | T11: 427846 | U11: 3709 | V11: 2161 | W11: 92996 | X11: 2985.1 | Y11: 2.73 | Z11: =IF(Y11<=2.41,10%,15%) -> 0.15
A12: 44102 | B12: 28608000 | C12: 79.72 | D12: 6704.9 | E12: 773.4 | F12: =YEAR(A12) -> 2020 | G12: =MONTH(A12) -> 9 | H12: =IF(OR(D12="",E12=""),"",D12*E12) -> 5185569.7 | I12: =IF(OR(B12="",C12="",config!$B$1=""),"",B12/(C12/config!$B$1)) -> 39366503 | J12: =IF(OR(H12="",C12="",config!$B$1=""),"",H12/(C12/config!$B$1)) -> 7135687.3 | L12: =IF(I12="","",LN(1+MAX(0,I12))) -> 17.488426 | M12: =IF(J12="","",LN(J12)) -> 15.780619 | N12: 86.62828 | O12: 85.713078 | P12: 94.031056 | Q12: 108.46186 | R12: 102.6852 | S12: 134.15573 | T12: 427846 | U12: 3709 | V12: 2161 | W12: 92996 | X12: 2602.6 | Y12: 3.0363 | Z12: =IF(Y12<=2.41,10%,15%) -> 0.15
A13: 44133 | B13: 25900000 | C13: 80.27 | D13: 6713.81 | E13: 788.27 | F13: =YEAR(A13) -> 2020 | G13: =MONTH(A13) -> 10 | H13: =IF(OR(D13="",E13=""),"",D13*E13) -> 5292295 | I13: =IF(OR(B13="",C13="",config!$B$1=""),"",B13/(C13/config!$B$1)) -> 35395914 | J13: =IF(OR(H13="",C13="",config!$B$1=""),"",H13/(C13/config!$B$1)) -> 7232649.3 | L13: =IF(I13="","",LN(1+MAX(0,I13))) -> 17.382107 | M13: =IF(J13="","",LN(J13)) -> 15.794116 | N13: 86.62828 | O13: 85.713078 | P13: 94.031056 | Q13: 108.46186 | R13: 102.6852 | S13: 134.15573 | T13: 427846 | U13: 3709 | V13: 2161 | W13: 92996 | X13: 2964.2 | Y13: 2.5125 | Z13: =IF(Y13<=2.41,10%,15%) -> 0.15
A14: 44164 | B14: =21360000 - 890000 -> 20470000 | C14: 80.16 | D14: 7068.91 | E14: 762.88 | F14: =YEAR(A14) -> 2020 | G14: =MONTH(A14) -> 11 | H14: =IF(OR(D14="",E14=""),"",D14*E14) -> 5392730.1 | I14: =IF(OR(B14="",C14="",config!$B$1=""),"",B14/(C14/config!$B$1)) -> 28013461 | J14: =IF(OR(H14="",C14="",config!$B$1=""),"",H14/(C14/config!$B$1)) -> 7380021.1 | L14: =IF(I14="","",LN(1+MAX(0,I14))) -> 17.148196 | M14: =IF(J14="","",LN(J14)) -> 15.814287 | N14: 86.62828 | O14: 85.713078 | P14: 94.031056 | Q14: 108.46186 | R14: 102.6852 | S14: 134.15573 | T14: 427846 | U14: 3709 | V14: 2161 | W14: 92996 | X14: 2773.3 | Y14: 2.3154 | Z14: =IF(Y14<=2.41,10%,15%) -> 0.1
A15: 44195 | B15: =21360000 - 890000 -> 20470000 | C15: 80.43 | D15: 7772.24 | E15: 734.73 | F15: =YEAR(A15) -> 2020 | G15: =MONTH(A15) -> 12 | H15: =IF(OR(D15="",E15=""),"",D15*E15) -> 5710497.9 | I15: =IF(OR(B15="",C15="",config!$B$1=""),"",B15/(C15/config!$B$1)) -> 27919421 | J15: =IF(OR(H15="",C15="",config!$B$1=""),"",H15/(C15/config!$B$1)) -> 7788656.2 | L15: =IF(I15="","",LN(1+MAX(0,I15))) -> 17.144833 | M15: =IF(J15="","",LN(J15)) -> 15.868179 | N15: 86.62828 | O15: 85.713078 | P15: 94.031056 | Q15: 108.46186 | R15: 102.6852 | S15: 134.15573 | T15: 427846 | U15: 3709 | V15: 2161 | W15: 92996 | X15: 1656.8 | Y15: 3.3534 | Z15: =IF(Y15<=2.41,10%,15%) -> 0.15
A16: 44227 | B16: 25200000 | C16: 80.99 | D16: 7972.15 | E16: 723.56 | F16: =YEAR(A16) -> 2021 | G16: =MONTH(A16) -> 1 | H16: =IF(OR(D16="",E16=""),"",D16*E16) -> 5768328.9 | I16: =IF(OR(B16="",C16="",config!$B$1=""),"",B16/(C16/config!$B$1)) -> 34133103 | J16: =IF(OR(H16="",C16="",config!$B$1=""),"",H16/(C16/config!$B$1)) -> 7813133.4 | L16: =IF(I16="","",LN(1+MAX(0,I16))) -> 17.345778 | M16: =IF(J16="","",LN(J16)) -> 15.871317 | N16: 86.62828 | O16: 85.713078 | P16: 94.031056 | Q16: 108.46186 | R16: 102.6852 | S16: 134.15573 | T16: 427846 | U16: 3709 | V16: 2161 | W16: 92996 | X16: 2359.644 | Y16: 2.86 | Z16: =IF(Y16<=2.41,10%,15%) -> 0.15
A17: 44228 | B17: 22800000 | C17: 81.14 | D17: 8470.94 | E17: 722.35398 | F17: =YEAR(A17) -> 2021 | G17: =MONTH(A17) -> 2 | H17: =IF(OR(D17="",E17=""),"",D17*E17) -> 6119017.3 | I17: =IF(OR(B17="",C17="",config!$B$1=""),"",B17/(C17/config!$B$1)) -> 30825240 | J17: =IF(OR(H17="",C17="",config!$B$1=""),"",H17/(C17/config!$B$1)) -> 8272814.8 | L17: =IF(I17="","",LN(1+MAX(0,I17))) -> 17.243844 | M17: =IF(J17="","",LN(J17)) -> 15.928485 | N17: 86.62828 | O17: 85.713078 | P17: 94.031056 | Q17: 108.46186 | R17: 102.6852 | S17: 134.15573 | T17: 427846 | U17: 3709 | V17: 2161 | W17: 92996 | X17: 2092.123 | Y17: 2.2644 | Z17: =IF(Y17<=2.41,10%,15%) -> 0.1 | AA17: =X17/1000 -> 2.092123
A18: 44256 | B18: 24000000 | C18: 81.45 | D18: 8988.2478 | E18: 726.10303 | F18: =YEAR(A18) -> 2021 | G18: =MONTH(A18) -> 3 | H18: =IF(OR(D18="",E18=""),"",D18*E18) -> 6526393.9 | I18: =IF(OR(B18="",C18="",config!$B$1=""),"",B18/(C18/config!$B$1)) -> 32324125 | J18: =IF(OR(H18="",C18="",config!$B$1=""),"",H18/(C18/config!$B$1)) -> 8789999 | K18: =IF(D2="","",IF(D2<=config!$B$2,1,0)) -> #NAME? | L18: =IF(I18="","",LN(1+MAX(0,I18))) -> 17.291324 | M18: =IF(J18="","",LN(J18)) -> 15.989125 | N18: 101.03916 | O18: 100.38071 | P18: 106.36509 | Q18: 107.89442 | R18: 102.05666 | S18: 133.86005 | T18: 489323 | U18: 4403 | V18: 2788 | W18: 107624 | X18: 2841.405 | Y18: 1.9972621 | Z18: =IF(Y18<=2.41,10%,15%) -> 0.1 | AA18: =X18/1000 -> 2.841405
A19: 44287 | B19: 12000000 | C19: 81.75 | D19: 9324.8175 | E19: 707.78751 | F19: =YEAR(A19) -> 2021 | G19: =MONTH(A19) -> 4 | H19: =IF(OR(D19="",E19=""),"",D19*E19) -> 6599989.4 | I19: =IF(OR(B19="",C19="",config!$B$1=""),"",B19/(C19/config!$B$1)) -> 16102752 | J19: =IF(OR(H19="",C19="",config!$B$1=""),"",H19/(C19/config!$B$1)) -> 8856499.5 | K19: {=_xludf.IF(D2="","",_xludf.IF(D2<=config!$B$2,1,0))} -> #NAME? | L19: =IF(I19="","",LN(1+MAX(0,I19))) -> 16.594501 | M19: =IF(J19="","",LN(J19)) -> 15.996662 | N19: 98.020102 | O19: 96.734218 | P19: 108.42121 | Q19: 111.80825 | R19: 106.5943 | S19: 134.99928 | T19: 465266 | U19: 4313 | V19: 2541 | W19: 90162 | X19: 2974.93 | Y19: 1.4579408 | Z19: =IF(Y19<=2.41,10%,15%) -> 0.1 | AA19: =X19/1000 -> 2.97493
A20: 44317 | B20: 30000000 | C20: 81.97 | D20: 10166.285 | E20: 713.40666 | F20: =YEAR(A20) -> 2021 | G20: =MONTH(A20) -> 5 | H20: =IF(OR(D20="",E20=""),"",D20*E20) -> 7252695.4 | I20: =IF(OR(B20="",C20="",config!$B$1=""),"",B20/(C20/config!$B$1)) -> 40148835 | J20: =IF(OR(H20="",C20="",config!$B$1=""),"",H20/(C20/config!$B$1)) -> 9706242.3 | L20: =IF(I20="","",LN(1+MAX(0,I20))) -> 17.508104 | M20: =IF(J20="","",LN(J20)) -> 16.08828 | N20: 100.16582 | O20: 98.684679 | P20: 112.1463 | Q20: 109.76611 | R20: 104.29036 | S20: 134.12158 | T20: 491090 | U20: 4486 | V20: 2921 | W20: 113945 | X20: 1452.806 | Y20: 2.7160208 | AA20: =X20/1000 -> 1.452806
A21: 44348 | B21: 24000000 | C21: 82.04 | D21: 9631.5 | E21: 728.64111 | F21: =YEAR(A21) -> 2021 | G21: =MONTH(A21) -> 6 | H21: =IF(OR(D21="",E21=""),"",D21*E21) -> 7017906.9 | I21: =IF(OR(B21="",C21="",config!$B$1=""),"",B21/(C21/config!$B$1)) -> 32091663 | J21: =IF(OR(H21="",C21="",config!$B$1=""),"",H21/(C21/config!$B$1)) -> 9384012.5 | K21: =IF(D21="","",IF(D21<=config!$B$2,1,0)) -> #NAME? | L21: =IF(I21="","",LN(1+MAX(0,I21))) -> 17.284107 | M21: =IF(J21="","",LN(J21)) -> 16.054518 | N21: 97.942967 | O21: 96.1355 | P21: 112.56299 | Q21: 109.55624 | R21: 104.21178 | S21: 133.32772 | T21: 482623 | U21: 4235 | V21: 2777 | W21: 115751 | X21: 1786.126 | Y21: 2.5994643 | Z21: =IF(Y21<=2.41,10%,15%) -> 0.15 | AA21: =X21/1000 -> 1.786126
A22: 44378 | B22: 45000000 | C22: 82.7 | D22: 9450.8205 | E22: 752.01477 | F22: =YEAR(A22) -> 2021 | G22: =MONTH(A22) -> 7 | H22: =IF(OR(D22="",E22=""),"",D22*E22) -> 7107156.6 | I22: =IF(OR(B22="",C22="",config!$B$1=""),"",B22/(C22/config!$B$1)) -> 59691657 | J22: =IF(OR(H22="",C22="",config!$B$1=""),"",H22/(C22/config!$B$1)) -> 9427510 | K22: =IF(D22="","",IF(D22<=config!$B$2,1,0)) -> #NAME? | L22: =IF(I22="","",LN(1+MAX(0,I22))) -> 17.904703 | M22: =IF(J22="","",LN(J22)) -> 16.059143 | N22: 97.690725 | O22: 95.062819 | P22: 118.94703 | Q22: 112.06613 | R22: 107.90391 | S22: 130.57919 | T22: 467798 | U22: 3901 | V22: 2657 | W22: 107399 | X22: 2165.532 | Y22: 2.7467771 | Z22: =IF(Y22<=2.41,10%,15%) -> 0.15 | AA22: =X22/1000 -> 2.165532
A23: 44409 | B23: 40800000 | C23: 83 | D23: 9370.1386 | E23: 780.83182 | F23: =YEAR(A23) -> 2021 | G23: =MONTH(A23) -> 8 | H23: =IF(OR(D23="",E23=""),"",D23*E23) -> 7316502.4 | I23: =IF(OR(B23="",C23="",config!$B$1=""),"",B23/(C23/config!$B$1)) -> 53924819 | J23: =IF(OR(H23="",C23="",config!$B$1=""),"",H23/(C23/config!$B$1)) -> 9670124.2 | K23: =IF(D23="","",IF(D23<=config!$B$2,1,0)) -> #NAME? | L23: =IF(I23="","",LN(1+MAX(0,I23))) -> 17.803101 | M23: =IF(J23="","",LN(J23)) -> 16.084552 | N23: 98.165141 | O23: 95.464397 | P23: 120.01061 | Q23: 111.03984 | R23: 106.18233 | S23: 132.6455 | T23: 464194 | U23: 4023 | V23: 3115 | W23: 116460 | X23: 2046.515 | Y23: 3.2693765 | Z23: =IF(Y23<=2.41,10%,15%) -> 0.15 | AA23: =X23/1000 -> 2.046515
A24: 44440 | B24: 36000000 | C24: 83.98 | D24: 9324.7095 | E24: 785.36912 | F24: =YEAR(A24) -> 2021 | G24: =MONTH(A24) -> 9 | H24: =IF(OR(D24="",E24=""),"",D24*E24) -> 7323339 | I24: =IF(OR(B24="",C24="",config!$B$1=""),"",B24/(C24/config!$B$1)) -> 47025482 | J24: =IF(OR(H24="",C24="",config!$B$1=""),"",H24/(C24/config!$B$1)) -> 9566209.6 | K24: =IF(D24="","",IF(D24<=config!$B$2,1,0)) -> #NAME? | L24: =IF(I24="","",LN(1+MAX(0,I24))) -> 17.6662 | M24: =IF(J24="","",LN(J24)) -> 16.073748 | N24: 94.012531 | O24: 90.752772 | P24: 120.37969 | Q24: 109.10897 | R24: 104.45063 | S24: 129.82867 | T24: 449068 | U24: 4143 | V24: 3055 | W24: 107966 | X24: 2003.079 | Y24: 2.9313546 | Z24: =IF(Y24<=2.41,10%,15%) -> 0.15 | AA24: =X24/1000 -> 2.003079
A25: 44470 | B25: 31200000 | C25: 85.1 | D25: 9829.219 | E25: 814.20593 | F25: =YEAR(A25) -> 2021 | G25: =MONTH(A25) -> 10 | H25: =IF(OR(D25="",E25=""),"",D25*E25) -> 8003008.4 | I25: =IF(OR(B25="",C25="",config!$B$1=""),"",B25/(C25/config!$B$1)) -> 40219036 | J25: =IF(OR(H25="",C25="",config!$B$1=""),"",H25/(C25/config!$B$1)) -> 10316452 | K25: =IF(D25="","",IF(D25<=config!$B$2,1,0)) -> #NAME? | L25: =IF(I25="","",LN(1+MAX(0,I25))) -> 17.509851 | M25: =IF(J25="","",LN(J25)) -> 16.14925 | N25: 104.08347 | O25: 99.989405 | P25: 137.19903 | Q25: 112.65874 | R25: 108.57591 | S25: 130.81872 | T25: 472261 | U25: 3944 | V25: 2947 | W25: 99449 | X25: 2364.952 | Y25: 2.0891059 | Z25: =IF(Y25<=2.41,10%,15%) -> 0.1 | AA25: =X25/1000 -> 2.364952
A26: 44501 | B26: 60000000 | C26: 85.53 | D26: 9728.9045 | E26: 813.50708 | F26: =YEAR(A26) -> 2021 | G26: =MONTH(A26) -> 11 | H26: =IF(OR(D26="",E26=""),"",D26*E26) -> 7914532.7 | I26: =IF(OR(B26="",C26="",config!$B$1=""),"",B26/(C26/config!$B$1)) -> 76955454 | J26: =IF(OR(H26="",C26="",config!$B$1=""),"",H26/(C26/config!$B$1)) -> 10151108 | K26: =IF(D26="","",IF(D26<=config!$B$2,1,0)) -> #NAME? | L26: =IF(I26="","",LN(1+MAX(0,I26))) -> 18.158737 | M26: =IF(J26="","",LN(J26)) -> 16.133093 | N26: 102.39899 | O26: 99.068489 | P26: 129.33832 | Q26: 113.28306 | R26: 109.54026 | S26: 129.93056 | T26: 483207 | U26: 3681 | V26: 3162 | W26: 107746 | X26: 2755.761 | Y26: 3.2848703 | Z26: =IF(Y26<=2.41,10%,15%) -> 0.15 | AA26: =X26/1000 -> 2.755761
A27: 44531 | B27: 60000000 | C27: 86.2 | D27: 9551.18 | E27: 849.81891 | F27: =YEAR(A27) -> 2021 | G27: =MONTH(A27) -> 12 | H27: =IF(OR(D27="",E27=""),"",D27*E27) -> 8116773.4 | I27: =IF(OR(B27="",C27="",config!$B$1=""),"",B27/(C27/config!$B$1)) -> 76357309 | J27: =IF(OR(H27="",C27="",config!$B$1=""),"",H27/(C27/config!$B$1)) -> 10329583 | K27: =IF(D27="","",IF(D27<=config!$B$2,1,0)) -> #NAME? | L27: =IF(I27="","",LN(1+MAX(0,I27))) -> 18.150934 | M27: =IF(J27="","",LN(J27)) -> 16.150522 | N27: 106.86136 | O27: 102.556 | P27: 141.6861 | Q27: 109.10638 | R27: 105.21441 | S27: 126.41739 | T27: 500982 | U27: 3677 | V27: 2888 | W27: 116758 | X27: 2699.495 | Y27: 3.7763263 | Z27: =IF(Y27<=2.41,10%,15%) -> 0.15 | AA27: =X27/1000 -> 2.699495
A28: 44562 | B28: 42000000 | C28: 87.23 | D28: 9782.3375 | E28: 819.82692 | F28: =YEAR(A28) -> 2022 | G28: =MONTH(A28) -> 1 | H28: =IF(OR(D28="",E28=""),"",D28*E28) -> 8019823.7 | I28: =IF(OR(B28="",C28="",config!$B$1=""),"",B28/(C28/config!$B$1)) -> 52818984 | J28: =IF(OR(H28="",C28="",config!$B$1=""),"",H28/(C28/config!$B$1)) -> 10085689 | K28: =IF(D28="","",IF(D28<=config!$B$2,1,0)) -> #NAME? | L28: =IF(I28="","",LN(1+MAX(0,I28))) -> 17.782381 | M28: =IF(J28="","",LN(J28)) -> 16.126628 | N28: 89.965888 | O28: 84.357026 | P28: 135.3342 | Q28: 111.26956 | R28: 106.98675 | S28: 130.31899 | T28: 427634 | U28: 3277 | V28: 2430 | W28: 95369 | X28: 2059.637 | Y28: 2.6639918 | Z28: =IF(Y28<=2.41,10%,15%) -> 0.15 | AA28: =X28/1000 -> 2.059637
A29: 44593 | B29: 39000000 | C29: 87.48 | D29: 9943.175 | E29: 806.89199 | F29: =YEAR(A29) -> 2022 | G29: =MONTH(A29) -> 2 | H29: =IF(OR(D29="",E29=""),"",D29*E29) -> 8023068.3 | I29: =IF(OR(B29="",C29="",config!$B$1=""),"",B29/(C29/config!$B$1)) -> 48906036 | J29: =IF(OR(H29="",C29="",config!$B$1=""),"",H29/(C29/config!$B$1)) -> 10060935 | K29: =IF(D29="","",IF(D29<=config!$B$2,1,0)) -> #NAME? | L29: =IF(I29="","",LN(1+MAX(0,I29))) -> 17.705411 | M29: =IF(J29="","",LN(J29)) -> 16.124171 | N29: 82.855543 | O29: 78.681042 | P29: 116.62176 | Q29: 115.65485 | R29: 111.22971 | S29: 135.33734 | T29: 397081 | U29: 3727 | V29: 2175 | W29: 86617 | X29: 1815.705 | Y29: 3.4900911 | Z29: =IF(Y29<=2.41,10%,15%) -> 0.15 | AA29: =X29/1000 -> 1.815705
A30: 44621 | B30: 42000000 | C30: 89.11 | D30: 10230.894 | E30: 798.41044 | F30: =YEAR(A30) -> 2022 | G30: =MONTH(A30) -> 3 | H30: =IF(OR(D30="",E30=""),"",D30*E30) -> 8168452.5 | I30: =IF(OR(B30="",C30="",config!$B$1=""),"",B30/(C30/config!$B$1)) -> 51704635 | J30: =IF(OR(H30="",C30="",config!$B$1=""),"",H30/(C30/config!$B$1)) -> 10055878 | K30: =IF(D30="","",IF(D30<=config!$B$2,1,0)) -> #NAME? | L30: =IF(I30="","",LN(1+MAX(0,I30))) -> 17.761058 | M30: =IF(J30="","",LN(J30)) -> 16.123668 | N30: 100.42424 | O30: 95.166357 | P30: 142.95358 | Q30: 115.86125 | R30: 111.14932 | S30: 136.81936 | T30: 459723 | U30: 4105 | V30: 2490 | W30: 110939 | X30: 2066.278 | Y30: 2.8406008 | Z30: =IF(Y30<=2.41,10%,15%) -> 0.15 | AA30: =X30/1000 -> 2.066278
A31: 44652 | B31: 30000000 | C31: 90.35 | D31: 10174.348 | E31: 818.92429 | F31: =YEAR(A31) -> 2022 | G31: =MONTH(A31) -> 4 | H31: =IF(OR(D31="",E31=""),"",D31*E31) -> 8332020.4 | I31: =IF(OR(B31="",C31="",config!$B$1=""),"",B31/(C31/config!$B$1)) -> 36425014 | J31: =IF(OR(H31="",C31="",config!$B$1=""),"",H31/(C31/config!$B$1)) -> 10116465 | K31: =IF(D31="","",IF(D31<=config!$B$2,1,0)) -> #NAME? | L31: =IF(I31="","",LN(1+MAX(0,I31))) -> 17.410766 | M31: =IF(J31="","",LN(J31)) -> 16.129675 | N31: 89.140243 | O31: 84.011303 | P31: 130.62661 | Q31: 120.00714 | R31: 116.16335 | S31: 137.10383 | T31: 420033 | U31: 3936 | V31: 2304 | W31: 86347 | X31: 1452.806 | Y31: 2.7160208 | Z31: =IF(Y31<=2.41,10%,15%) -> 0.15 | AA31: =X31/1000 -> 1.452806
A32: 44682 | B32: 21000000 | C32: 91.43 | D32: 9395.0273 | E32: 848.25885 | F32: =YEAR(A32) -> 2022 | G32: =MONTH(A32) -> 5 | H32: =IF(OR(D32="",E32=""),"",D32*E32) -> 7969415.1 | I32: =IF(OR(B32="",C32="",config!$B$1=""),"",B32/(C32/config!$B$1)) -> 25196325 | J32: =IF(OR(H32="",C32="",config!$B$1=""),"",H32/(C32/config!$B$1)) -> 9561903.5 | K32: =IF(D32="","",IF(D32<=config!$B$2,1,0)) -> #NAME? | L32: =IF(I32="","",LN(1+MAX(0,I32))) -> 17.042209 | M32: =IF(J32="","",LN(J32)) -> 16.073297 | N32: 100.36273 | O32: 95.779165 | P32: 137.43777 | Q32: 120.21809 | R32: 115.36935 | S32: 141.78475 | T32: 477610 | U32: 3952 | V32: 2718 | W32: 105992 | X32: 1167.221 | Y32: 2.6787885 | Z32: =IF(Y32<=2.41,10%,15%) -> 0.15 | AA32: =X32/1000 -> 1.167221
... A40: 44927 | B40: 87000000 | C40: 98 | D40: 9007.3464 | E40: 825.07181 | F40: =YEAR(A40) -> 2023 | G40: =MONTH(A40) -> 1 | H40: =IF(OR(D40="",E40=""),"",D40*E40) -> 7431707.6 | I40: =IF(OR(B40="",C40="",config!$B$1=""),"",B40/(C40/config!$B$1)) -> 97386735 | J40: =IF(OR(H40="",C40="",config!$B$1=""),"",H40/(C40/config!$B$1)) -> 8318962.5 | K40: =IF(D40="","",IF(D40<=config!$B$2,1,0)) -> #NAME? | L40: =IF(I40="","",LN(1+MAX(0,I40))) -> 18.394201 | M40: =IF(J40="","",LN(J40)) -> 15.934048 | N40: 93.164226 | O40: 86.515517 | P40: 146.94354 | Q40: 131.91892 | R40: 126.8741 | S40: 154.35769 | T40: 433405 | U40: 3772 | V40: 2421 | W40: 103027 | X40: 3479.284 | Y40: 4.15195 | Z40: =IF(Y40<=2.41,10%,15%) -> 0.15 | AA40: =X40/1000 -> 3.479284
A41: 44958 | B41: 28200000 | C41: 97.93 | D41: 8936.587 | E41: 801.34175 | F41: =YEAR(A41) -> 2023 | G41: =MONTH(A41) -> 2 | H41: =IF(OR(D41="",E41=""),"",D41*E41) -> 7161260.3 | I41: =IF(OR(B41="",C41="",config!$B$1=""),"",B41/(C41/config!$B$1)) -> 31589298 | J41: =IF(OR(H41="",C41="",config!$B$1=""),"",H41/(C41/config!$B$1)) -> 8021957 | K41: =IF(D41="","",IF(D41<=config!$B$2,1,0)) -> #NAME? | L41: =IF(I41="","",LN(1+MAX(0,I41))) -> 17.268329 | M41: =IF(J41="","",LN(J41)) -> 15.897693 | N41: 84.417567 | O41: 79.614246 | P41: 123.27012 | Q41: 130.99041 | R41: 124.88499 | S41: 158.1466 | T41: 382219 | U41: 3747 | V41: 2616 | W41: 100466 | X41: 2268.053 | Y41: 2.2169837 | Z41: =IF(Y41<=2.41,10%,15%) -> 0.1
A42: 44986 | B42: 42000000 | C42: 99 | D42: 8856.3109 | E42: 807.39867 | F42: =YEAR(A42) -> 2023 | G42: =MONTH(A42) -> 3 | H42: =IF(OR(D42="",E42=""),"",D42*E42) -> 7150573.6 | I42: =IF(OR(B42="",C42="",config!$B$1=""),"",B42/(C42/config!$B$1)) -> 46539394 | J42: =IF(OR(H42="",C42="",config!$B$1=""),"",H42/(C42/config!$B$1)) -> 7923413.4 | K42: =IF(D42="","",IF(D42<=config!$B$2,1,0)) -> #NAME? | L42: =IF(I42="","",LN(1+MAX(0,I42))) -> 17.65581 | M42: =IF(J42="","",LN(J42)) -> 15.885333 | N42: 92.723836 | O42: 86.928677 | P42: 139.59905 | Q42: 127.88055 | R42: 119.91178 | S42: 163.32468 | T42: 437837 | U42: 4063 | V42: 3710 | W42: 122532 | X42: 2339.843 | Y42: 3.058437 | Z42: =IF(Y42<=2.41,10%,15%) -> 0.15
A43: 45017 | B43: 24960000 | C43: 99.3 | D43: 8809.1575 | E43: 804.97701 | F43: =YEAR(A43) -> 2023 | G43: =MONTH(A43) -> 4 | H43: =IF(OR(D43="",E43=""),"",D43*E43) -> 7091169.3 | I43: =IF(OR(B43="",C43="",config!$B$1=""),"",B43/(C43/config!$B$1)) -> 27574139 | J43: =IF(OR(H43="",C43="",config!$B$1=""),"",H43/(C43/config!$B$1)) -> 7833849.6 | K43: =IF(D43="","",IF(D43<=config!$B$2,1,0)) -> #NAME? | L43: =IF(I43="","",LN(1+MAX(0,I43))) -> 17.132389 | M43: =IF(J43="","",LN(J43)) -> 15.873965 | N43: 91.32933 | O43: 86.045183 | P43: 134.07112 | Q43: 128.40211 | R43: 119.51368 | S43: 167.93677 | T43: 414753 | U43: 3280 | V43: 3001 | W43: 110143 | X43: 1938.567 | Y43: 2.944019 | Z43: =IF(Y43<=2,10%,IF(Y43<=2.4,13%,15.5%)) -> 0.155
A44: 45047 | B44: 26100000 | C44: 99.41 | D44: 8243.1561 | E44: 799.35108 | F44: =YEAR(A44) -> 2023 | G44: =MONTH(A44) -> 5 | H44: =IF(OR(D44="",E44=""),"",D44*E44) -> 6589175.7 | I44: =IF(OR(B44="",C44="",config!$B$1=""),"",B44/(C44/config!$B$1)) -> 28801630 | J44: =IF(OR(H44="",C44="",config!$B$1=""),"",H44/(C44/config!$B$1)) -> 7271226 | K44: =IF(D44="","",IF(D44<=config!$B$2,1,0)) -> #NAME? | L44: =IF(I44="","",LN(1+MAX(0,I44))) -> 17.175943 | M44: =IF(J44="","",LN(J44)) -> 15.799435 | N44: 89.87846 | O44: 83.116479 | P44: 144.57399 | Q44: 129.27534 | R44: 119.71928 | S44: 171.77955 | T44: 411187 | U44: 3361 | V44: 2915 | W44: 102852 | X44: 1961.32 | Y44: 2.8862021 | Z44: =IF(Y44<=2,10%,IF(Y44<=2.4,13%,15.5%)) -> 0.155
A45: 45078 | B45: 40800000 | C45: 99.26 | D45: 8396.5177 | E45: 799.5102 | F45: =YEAR(A45) -> 2023 | G45: =MONTH(A45) -> 6 | H45: =IF(OR(D45="",E45=""),"",D45*E45) -> 6713101.5 | I45: =IF(OR(B45="",C45="",config!$B$1=""),"",B45/(C45/config!$B$1)) -> 45091275 | J45: =IF(OR(H45="",C45="",config!$B$1=""),"",H45/(C45/config!$B$1)) -> 7419174.3 | K45: =IF(D45="","",IF(D45<=config!$B$2,1,0)) -> #NAME? | L45: =IF(I45="","",LN(1+MAX(0,I45))) -> 17.624199 | M45: =IF(J45="","",LN(J45)) -> 15.819578 | N45: 96.701911 | O45: 91.848191 | P45: 135.96212 | Q45: 129.72187 | R45: 120.60966 | S45: 170.25188 | T45: 458577 | U45: 3857 | V45: 3311 | W45: 115705 | X45: 2015.077 | Y45: 3.4943986 | Z45: =IF(Y45<=2,10%,IF(Y45<=2.4,13%,15.5%)) -> 0.155
A46: 45108 | B46: 36000000 | C46: 99.61 | D46: 8476.679 | E46: 815.01689 | F46: =YEAR(A46) -> 2023 | G46: =MONTH(A46) -> 7 | H46: =IF(OR(D46="",E46=""),"",D46*E46) -> 6908636.6 | I46: =IF(OR(B46="",C46="",config!$B$1=""),"",B46/(C46/config!$B$1)) -> 39646622 | J46: =IF(OR(H46="",C46="",config!$B$1=""),"",H46/(C46/config!$B$1)) -> 7608447.3 | K46: =IF(D46="","",IF(D46<=config!$B$2,1,0)) -> #NAME? | L46: =IF(I46="","",LN(1+MAX(0,I46))) -> 17.495516 | M46: =IF(J46="","",LN(J46)) -> 15.84477 | N46: 94.085373 | O46: 88.158714 | P46: 142.02425 | Q46: 131.48805 | R46: 122.11281 | S46: 173.18802 | T46: 435120 | U46: 4140 | V46: 2895 | W46: 119655 | X46: 2719.032 | Y46: 2.5476853 | Z46: =IF(Y46<=2,10%,IF(Y46<=2.4,13%,15.5%)) -> 0.155
A47: 45139 | B47: 44640000 | C47: 99.72 | D47: 8347.8283 | E47: 856.54436 | F47: =YEAR(A47) -> 2023 | G47: =MONTH(A47) -> 8 | H47: =IF(OR(D47="",E47=""),"",D47*E47) -> 7150285.2 | I47: =IF(OR(B47="",C47="",config!$B$1=""),"",B47/(C47/config!$B$1)) -> 49107581 | J47: =IF(OR(H47="",C47="",config!$B$1=""),"",H47/(C47/config!$B$1)) -> 7865887.4 | K47: =IF(D47="","",IF(D47<=config!$B$2,1,0)) -> #NAME? | L47: =IF(I47="","",LN(1+MAX(0,I47))) -> 17.709524 | M47: =IF(J47="","",LN(J47)) -> 15.878046 | N47: 93.664342 | O47: 87.218549 | P47: 145.80232 | Q47: 129.28827 | R47: 119.28719 | S47: 173.77186 | T47: 439295 | U47: 3535 | V47: 2831 | W47: 119278 | X47: 2615.109 | Y47: 2.9251092 | Z47: =IF(Y47<=2,10%,IF(Y47<=2.4,13%,15.5%)) -> 0.155
...
